Workbook
Name ALW_Cost: #REF!
Name ASE_Cost: #REF!
Name CO_Cost: #REF!
Name CO_Rate: #REF!
Name Country: #REF!
Name CPM_Cost: #REF!
Name CPM_Rate: #REF!
Name EUR_FY: #REF!
Name ExRates: #REF!
Name FA_Cost: #REF!
Name FA_hours: #REF!
Name FA_Rate: #REF!
Name FACTORS: #REF!
Name HTL_Cost: #REF!
Name INCOTERMS: #REF!
Name LE_Cost: #REF!
Name PA_Cost: #REF!
Name PA_Rate: #REF!
Name PB_Cur: #REF!
Name PM_Cost: #REF!
Name PU_Cost: #REF!
Name PU_Rate: #REF!
Name QDATE: #REF!
Name SE_Cost: #REF!
Name SE_Rate: #REF!
Name SepShip: #REF!
Name SparePct: #REF!
Name SPM_Cost: #REF!
Name SPM_Rate: #REF!
Name SSE_Cost: #REF!
Name SSE_Rate: #REF!
Name TR_Cost: #REF!
Name TRP_Cost: #REF!
Name USD_FY: #REF!

Sheet Title
B4: Name_Project:
B5: Name executor: | C5: Багдасарян А.А.

Sheet Service
E1: Наименование | F1: Колличество | G1: Описание | H1: Ширина на DIN
B2: синхронизация контролера | D2: module AI | E2: АРКС400.AIO.2.32/0.CLU22 | F2: 32 | G2: ТП, мВ, ТС по 3х-проводной и 4х-проводной схеме в любом сочетании** | H2: 164
B3: Yes | D3: module AI | E3: АРКС400.AIO.2.16/0.CLU2 | F3: 16 | G3: ТП, мВ, ТС по 3х-проводной и 4х-проводной схеме в любом сочетании** | H3: 164
B4: No | D4: module AI | E4: АРКС400.AIO.2.08/0.CLU2 | F4: 8 | G4: ТП, мВ, ТС по 3х-проводной и 4х-проводной схеме в любом сочетании** | H4: 164
D5: module AI | E5: АРКС400.AIO.1.16/0.CLU2 | F5: 16 | G5: 16 каналов ввода и 0 каналов вывода, 4-20 мА/0-5 мА/0-10 В в любом сочетании, 0-10 В поддержан на первых 8 каналах ввода; | H5: 157
D6: module AI | E6: АРКС400.AIO.1.08/0.CLU2 | F6: 8 | G6: 8 каналов ввода и 2 канала вывода, 4-20 мА/0-5 мА/0-10 В в любом сочетании; | H6: 157
D7: module AI | E7: АРКС400.AIO.3.12/0.CLU2 | F7: 12 | G7: 12 каналов ввода и 0 каналов вывода, 4-20 мА/0-5 мА/0-10 В в любом сочетании, 0-10 В поддержан на первых 8 каналах ввода; | H7: 164
D8: module AI | E8: АРКС400.AIO.1.16/0.CLU2 | F8: 8 | G8: 0-10 В поддержан на первых 8 каналах ввода; | H8: 157
D9: module AI | E9: АРКС400.AIO.1.08/0.CLU2 | F9: 8 | G9: 0-10 В в любом сочетании; | H9: 157
D10: module AI | E10: АРКС400.AIO.3.12/0.CLU2 | F10: 0 | G10: 12 каналов ввода и 0 каналов вывода, 4-20 мА/0-5 мА/0-10 В в любом сочетании, 0-10 В поддержан на первых 8 каналах ввода; | H10: 164
D11: module AI | E11: АРКС400.AIO.2.32/2.CLU22 | F11: 32 | G11: ТП, мВ, ТС по 3х-проводной и 4х-проводной схеме в любом сочетании** | H11: 164
D12: module AI | E12: АРКС400.AIO.2.16/2.CLU2 | F12: 16 | G12: ТП, мВ, ТС по 3х-проводной и 4х-проводной схеме в любом сочетании** | H12: 164
D13: module AI | E13: АРКС400.AIO.2.08/2.CLU2 | F13: 8 | G13: ТП, мВ, ТС по 3х-проводной и 4х-проводной схеме в любом сочетании** | H13: 164
D14: module AI | E14: АРКС400.AIO.1.16/2.CLU2 | F14: 16 | G14: 16 каналов ввода и 0 каналов вывода, 4-20 мА/0-5 мА/0-10 В в любом сочетании, 0-10 В поддержан на первых 8 каналах ввода; | H14: 157
D15: module AI | E15: АРКС400.AIO.1.08/2.CLU2 | F15: 8 | G15: 8 каналов ввода и 2 канала вывода, 4-20 мА/0-5 мА/0-10 В в любом сочетании; | H15: 157
D16: module AI | E16: АРКС400.AIO.3.12/6.CLU2 | F16: 12 | G16: 12 каналов ввода и 2 канала вывода, 4-20 мА/0-5 мА | H16: 164
... D21: module AO | E21: АРКС400.AIO.1.08/2.CLU2 | F21: 2 | G21: 0-20 мА, 4-20 мА, 0-5 мА, 0-10 В | H21: 157
D22: module AO | E22: АРКС400.AIO.3.12/6.CLU2 | F22: 6 | H22: 164
D23: module AO | E23: АРКС400.AIO.1.00/2.CLU2 | F23: 2 | G23: 0-20 мА, 4-20 мА, 0-5 мА, 0-10 В | H23: 157
D24: module AO | E24: АРКС400.AIO.3.00/6.CLU2 | F24: 6 | H24: 164
D25: module AO | E25: АРКС400.AIO.2.32/2.CLU22 | F25: 2 | H25: 164
D26: module AO | E26: АРКС400.AIO.2.16/2.CLU2 | F26: 2 | H26: 164
D27: module AO | E27: АРКС400.AIO.2.08/2.CLU2 | F27: 2 | H27: 164
D28: module AO | E28: АРКС400.AIO.3.12/6.CLU2 | F28: 6 | H28: 164
D29: module DI | E29: АРКС400.DIO.64.CLD | F29: 8 | G29: 64 канала ввода/вывода (8 групп по 8 каналов в группе с программным назначением группы на ввод или вывод), в комплекте с клеммным модулем АРКС400.CLD | H29: 157
E30: АРКС400.DIO.32.CLD | F30: 4 | G30: Модуль АРКС400.DIO.64.CLD состоит из электронного блока АРКС400.DIO (может быть также на 32 канала и называется АРКС400.DIO.32 – 4 группы по 8 каналов) и нижнего клеммного модуля АРКС400.CLD. | H30: 157
D35: module DO
D39: term_board | E39: АРКС400.KDI.8AC220 | F39: 8 | G39: ввод 220 В, переменный ток | H39: 110
E40: АРКС400.KDI.8DC220 | F40: 8 | G40: ввод 220 В, постоянный ток | H40: 110
E41: АРКС400.KDI.8DC24 | F41: 8 | G41: ввод 24 В, постоянный ток | H41: 110
E42: АРКС400.KDI.8AC24 | F42: 8 | G42: ввод 24 В, переменный, постоянный или выпрямленный ток | H42: 110
E43: АРКС400.KDO.8SR | F43: 8 | H43: 100
E44: АРКС400.KDO.8R | F44: 8 | H44: 100
D49: module ModBus
D51: cables | E51: FRC-10-30 | G51: Шлейф
D55: Module HSC
D56: Ethernet | E56: GM010-ISW-24L-C01 | F56: 24
E57: YN-SI1300A-8FE-T2-PR | F57: 8
E58: YN-SI2700A-4GX-8GP | F58: 8
E59: YN-SI2700AE RM | F59: 8
...

Sheet 1
E3: Шкаф | G3: Аналоговые входы/выходы | V3: Дискретные входы/выходы | AE3: Итого
G4: AI | H4: AI | I4: AI | J4: AI | K4: AI | L4: AI | M4: AI | N4: AI | O4: AI | P4: AI HART | Q4: AI HART | R4: AO HART | S4: AO HART | T4: AO | U4: AO | V4: DI | W4: DI | X4: DI | Y4: DI | Z4: DO | AA4: DO | AB4: DO | AC4: FI | AD4: FI | AF4: Ethernet | AG4: Profibus DP | AH4: Foundation Fieldbus | AI4: Modbus | AJ4: Modbus
G5: TC | H5: TC | I5: RTD | J5: RTD | K5: RTD > 4-20 мА | L5: 0-10 В | M5: 0-10 В | N5: 4-20 мА | O5: 4-20 мА | P5: 4-20 мА | Q5: 4-20 мА | R5: 4-20 мА/ 0-10 В | S5: 4-20 мА/ 0-10 В | T5: 4-20 мА/ 0-10 В | U5: 4-20 мА/ 0-10 В | V5: сухой конт. | W5: сухой конт. | X5: NAMUR | Y5: сухой конт. | Z5: сухой конт. | AA5: сухой конт. | AB5: сухой конт. | AC5: частотно-импульсный | AD5: частотно-импульсный | AI5: RS232 | AJ5: RS485
G6: Exi | I6: Exi | K6: Exi | L6: Exi | N6: Exi | P6: Exi | R6: Exi | T6: Exi | V6: Exi | AA6: Exi | AC6: Exi
G7: 4-х пров.сх. | H7: 4-х пров.сх. | I7: 4-х пров.сх. | J7: 4-х пров.сх. | K7: 2-х пров.сх. | L7: 2-х пров.сх. | M7: 2-х пров.сх. | N7: 2-х пров.сх. | O7: 2-х пров.сх. | P7: 2-х пров.сх. | Q7: 2-х пров.сх. | R7: 2-х пров.сх. | S7: 2-х пров.сх. | T7: 2-х пров.сх. | U7: 2-х пров.сх. | V7: 24V DC | W7: 24V DC | X7: 24V DC | Y7: 220V AC | Z7: 220V AC | AA7: 24V DC | AB7: 24V DC | AC7: 2-х пров.сх. | AD7: 2-х пров.сх. | AF7: интерфейсов | AG7: интерфейсов | AH7: интерфейсов | AI7: интерфейсов | AJ7: интерфейсов
E8: Сигналов | G8: 1 | H8: 2 | I8: 3 | J8: 4 | K8: 5 | L8: 6 | M8: 7 | N8: 8 | O8: 9 | P8: 10 | Q8: 11 | R8: 12 | S8: 13 | T8: 14 | U8: 15 | V8: 16 | W8: 17 | X8: 18 | Y8: 19 | Z8: 20 | AA8: 21 | AB8: 22 | AC8: 23 | AD8: 24 | AE8: =SUM(G8:AD8) -> 300
E9: Резерв | F9: 0 | G9: =ROUNDUP(G8*$F9,0) -> 0 | H9: =ROUNDUP(H8*$F9,0) -> 0 | I9: =ROUNDUP(I8*$F9,0) -> 0 | J9: =ROUNDUP(J8*$F9,0) -> 0 | K9: =ROUNDUP(K8*$F9,0) -> 0 | L9: =ROUNDUP(L8*$F9,0) -> 0 | M9: =ROUNDUP(M8*$F9,0) -> 0 | N9: =ROUNDUP(N8*$F9,0) -> 0 | ... AD9: =ROUNDUP(AD8*$F9,0) -> 0 | AE9: =SUM(G9:AD9) -> 0 | AF9: =ROUNDUP(AF8*$F9,0) -> 0 | AG9: =ROUNDUP(AG8*$F9,0) -> 0 | AH9: =ROUNDUP(AH8*$F9,0) -> 0 | AI9: =ROUNDUP(AI8*$F9,0) -> 0 | AJ9: =ROUNDUP(AJ8*$F9,0) -> 0
E10: Итого c резервом | G10: =IF(SUM(G8:G9)=0,"0",SUM(G8:G9)) -> 1 | H10: =IF(SUM(H8:H9)=0,"0",SUM(H8:H9)) -> 2 | I10: =IF(SUM(I8:I9)=0,"0",SUM(I8:I9)) -> 3 | J10: =IF(SUM(J8:J9)=0,"0",SUM(J8:J9)) -> 4 | K10: =IF(SUM(K8:K9)=0,"0",SUM(K8:K9)) -> 5 | L10: =IF(SUM(L8:L9)=0,"0",SUM(L8:L9)) -> 6 | M10: =IF(SUM(M8:M9)=0,"0",SUM(M8:M9)) -> 7 | N10: =IF(SUM(N8:N9)=0,"0",SUM(N8:N9)) -> 8 | ... AJ10: =IF(SUM(AJ8:AJ9)=0,"0",SUM(AJ8:AJ9)) -> 0
B11: =$E$3 -> Шкаф
B12: Описание | C12: Резервирование контроллеров | D12: Yes
C13: Реле/Барьеры отдельно | D13: No
C14: Резервирование AI | D14: 1
C15: Резервирование AO | D15: 1
C16: Резервирование DI | D16: 1
C17: Резервирование DO | D17: 1
B18: 1800 | C18: Количество DIN-реек на шкаф | D18: 4
C19: Процент свободного места в шкафе | D19: 0.2
C20: Процент сигналов с питанием от шкафа | D20: 0
C21: Шкафов | D21: =ROUNDUP((SUM(D26,D30:D33)*157+SUM(D28:D29)*164+SUM(D34:D37)*110+D27*35+D38*76+SUM(D49:D54)*13)*(1+D19)/(D18*1700),0) -> 2
C22: Нагрузка, Вт | D22: =D26*5.5+D33*1.5+SUM(D30:D32)*3+SUM(D28:D29)*2+D37*1.4+D36*3.3+SUM(D34:D35)*2+D27*3.4+D38*15+D49*0.07+D50*0.07+D51*0.571+D52*0.72+D53*1.8+D54*0.72+D47*1+D48*5 -> 333.895
B23: ФПО | C23: АРКС.конфигуратор.1.640 | D23: 1
B24: СРВ | C24: АРКС.СРВ.1.w/l.640 | D24: 1
B25: БПО | C25: АРКС.СРВ.1.lc/wc.640 | D25: =D26 -> 2
B26: CP | C26: АРКС400.P410 | D26: =IF(D12="Yes",2,1)*ROUNDUP(SUM(AE10)/VLOOKUP(C26,Service!$E$79:$F$79,2,0),0) -> 2
B27: PS I/O | C27: АРКС400.PS.4/24 | D27: =ROUNDUP(D20*SUM(L10:Q10)/4,0) -> 0
B28: module AI TC/RTD | C28: АРКС400.AIO.2.32/0.CLU22 | D28: =MAX(0,ROUNDUP((SUM($G$10:$H$10)+SUM($I$10:$J$10)*2-D29*VLOOKUP(C29,Service!E11:F13,2,0)/D14)/VLOOKUP(C28,Service!$E$2:$F$4,2,FALSE),0)*D14) -> 0
B29: module AI TC/RTD, AO (U,I) | C29: АРКС400.AIO.2.32/2.CLU22 | D29: =MAX(MIN( ROUNDUP((SUM($G$10:$H$10)+SUM($I$10:$J$10)*2)/VLOOKUP(C29,Service!E11:F13,2,0),0)*D14, ROUNDUP((SUM($R$10:$U$10)/VLOOKUP(C31,Service!E20:F22,2,FALSE)-D31)*D15,0) ),0) -> 1
B30: module AI (U,I) | C30: АРКС400.AIO.1.16/0.CLU2 | D30: =MAX(IFERROR(ROUNDUP((SUM(L10:M10)-D31*VLOOKUP(C31,Service!$E$17:$F$19,2,0)/D14)/VLOOKUP(C30,Service!$E$8:$F$10,2,0), 0),0), ROUNDUP((SUM(K10:Q10)-D31*VLOOKUP(C31,Service!$E$14:$F$16,2,0)/D14)/VLOOKUP(C30,Service!$E$5:$F$7,2,0),0),0)*D14 -> 0
B31: module AIO (U,I) | C31: АРКС400.AIO.1.16/2.CLU2 | D31: =MIN( MAX( D14*IFERROR(ROUNDUP(SUM(L10:M10)/VLOOKUP(C31,Service!E17:F19,2,0), 0),0), D14*ROUNDUP(SUM(K10:Q10)/VLOOKUP(C31,Service!E14:F16,2,0), 0), 0), D15*ROUNDUP(SUM($R$10:$U$10)/VLOOKUP(C31,Service!$E$20:$F$22,2,FALSE),0)) -> 4
B32: module AO | C32: АРКС400.AIO.1.00/2.CLU2 | D32: =ROUNDUP(SUM($R$10:$U$10)/VLOOKUP(C31,Service!E20:F22,2,FALSE),0)*D15-D31-D29 -> 22
B33: module DI | C33: АРКС400.DIO.64.CLD | D33: =ROUNDUP(MAX(0,D34+D35-4*D26/IF(D12="Yes",2,1))/VLOOKUP(C33,Service!E29:F30,2,0) +MAX(0,D36+D37-4*D26/IF(D12="Yes",2,1))/VLOOKUP(C33,Service!E29:F30,2,0),0) -> 3
B34: DI 220 | C34: АРКС400.KDI.8AC220 | D34: =D16*ROUNDUP(SUM(Y10)/8,0) -> 3
B35: DI 24 | C35: АРКС400.KDI.8DC24 | D35: =D16*ROUNDUP(SUM(V10:X10,X10,AC10:AD10)/8,0) -> 15
B36: DO 220 | C36: АРКС400.KDO.8R | D36: =D17*ROUNDUP(SUM(Z10)/8,0) -> 3
B37: DO 24 | C37: АРКС400.KDO.8SR | D37: =D17*ROUNDUP(SUM(AA10:AB10)/8,0) -> 6
B38: =Service!$D$56 -> Ethernet | C38: YN-SI2700AE RM | D38: =ROUNDUP(($AF$10)/VLOOKUP(C38,Service!$E$56:$F$59,2,FALSE),0) -> 0
B39: =Service!D60 -> Profibus DP | C39: MGate 5111 | D39: =ROUNDUP(($AG$10)/VLOOKUP(C39,Service!E60:F62,2,FALSE),0) -> 0
B40: =Service!D63 -> Foundation Fieldbus | C40: G0313 | D40: =ROUNDUP(($AH$10)/VLOOKUP(C40,Service!E63:F65,2,FALSE),0) -> 0
B41: connector1 | C41: DS1016-40 | D41: =D26 -> 2
B42: connector2 | C42: DS1016-20 | D42: =D26*2+D33*IF(C33="АРКС400.DIO.32.CLD",2,4) -> 16
...

Sheet 1 схема
E1: ='1'!E3 -> Шкаф
E2: ='1'!C45 -> NDR-120-24
E3: ='1'!D45 -> 6
E4: ='1'!C46 -> DRDN20-24
E5: ='1'!D46 -> 3
E6: ='1'!C26 -> АРКС400.P410
E7: ='1'!D26 -> 2
E8: ='1'!C27 -> АРКС400.PS.4/24
E9: ='1'!D27 -> 0
E11: Сеть Modbus
F14: ='1'!D28 -> 0 | T14: ='1'!D30+'1'!D31 -> 4 | AT14: ='1'!D31+'1'!D32 -> 26 | BH14: =IF(AND(SUM(BI19:CJ19)>0,'1'!D33=0),"-",'1'!D33) -> 3
F15: ='1'!C28 -> АРКС400.AIO.2.32/0.CLU22 | M15: ='1'!C29 -> АРКС400.AIO.2.32/2.CLU22 | T15: ='1'!C30 -> АРКС400.AIO.1.16/0.CLU2 | AF15: ='1'!C31 -> АРКС400.AIO.1.16/2.CLU2 | AT15: ='1'!C29 -> АРКС400.AIO.2.32/2.CLU22 | AX15: ='1'!C31 -> АРКС400.AIO.1.16/2.CLU2 | BB15: ='1'!C32 -> АРКС400.AIO.1.00/2.CLU2 | BH15: ='1'!C33 -> АРКС400.DIO.64.CLD
F16: Каналов: | R16: =VLOOKUP(F15,Service!$E$2:$F$56,2,0) -> 32 | T16: Каналов: | AO16: =VLOOKUP(T15,Service!$E$2:$F$56,2,0) -> 16 | AT16: Каналов: | BF16: =VLOOKUP(AT15,Service!$E$20:$F$56,2,0) -> 2 | BH16: Разъемов: | CK16: 8
AQ17: В станцию КИП
AJ19: =ROUNDUP((AK38)/AK22,0) -> 1 | AM19: =ROUNDUP((AN38)/AN22,0) -> 1 | AQ19: ='1'!D48 -> 4 | AU19: =ROUNDUP((AV38)/AV22,0) -> 1 | AX19: =ROUNDUP((AY38)/AY22,0) -> 1 | BI19: ='1'!$D$35 -> 15 | BY19: ='1'!$D$34 -> 3 | CB19: ='1'!$D$36 -> 3 | CE19: ='1'!$D$37 -> 6 | CM19: ='1'!D38 -> 0 | CP19: ='1'!D39 -> 0 | CS19: ='1'!D40 -> 0
AJ20: ='1'!$B$47 -> Hart Мультиплексор | AM20: ='1'!$B$47 -> Hart Мультиплексор | AQ20: ='1'!B48 -> Конвертер RS-485/Ethernet | AU20: ='1'!$B$47 -> Hart Мультиплексор | AX20: ='1'!$B$47 -> Hart Мультиплексор | BI20: ='1'!$C$35 -> АРКС400.KDI.8DC24 | BY20: ='1'!$C$34 -> АРКС400.KDI.8AC220 | CB20: ='1'!$C$36 -> АРКС400.KDO.8R | CE20: ='1'!$C$37 -> АРКС400.KDO.8SR | CM20: ='1'!C38 -> YN-SI2700AE RM | CP20: ='1'!C39 -> MGate 5111 | CS20: ='1'!C40 -> G0313
AJ21: ='1'!$C$47 -> TREI S240HC-0 | AM21: ='1'!$C$47 -> TREI S240HC-0 | AQ21: ='1'!C48 -> tDS-718 CR | AU21: ='1'!$C$47 -> TREI S240HC-0 | AX21: ='1'!$C$47 -> TREI S240HC-0 | BI21: Ввод 24 В постоянный | BY21: Ввод 220 В переменный | CB21: Вывод 220 В переменный | CE21: Вывод 24 В постоянный | CM21: Каналов: | CN21: =VLOOKUP($CM$20,Service!$E$56:$F$59,2,0) -> 8 | CP21: Каналов: | CQ21: =VLOOKUP(CP20,Service!E60:F62,2,0) -> 1 | CS21: Каналов: | CT21: =VLOOKUP(CS20,Service!E63:F65,2,0) -> 1
AJ22: Каналов: | AK22: =VLOOKUP(AJ21,Service!$E$131:$F$140,2,0) -> 16 | AM22: Каналов: | AN22: =VLOOKUP(AM21,Service!$E$131:$F$140,2,0) -> 16 | AQ22: Каналов: | AR22: =VLOOKUP(AQ21,Service!E141:F150,2,0) -> 1 | AU22: Каналов: | AV22: =VLOOKUP(AM21,Service!$E$131:$F$140,2,0) -> 16 | AX22: Каналов: | AY22: =VLOOKUP(AM21,Service!$E$131:$F$140,2,0) -> 16 | BI22: Каналов: | BW22: 8 | BY22: Каналов: | BZ22: 8 | CB22: Каналов: | CC22: 8 | CE22: Каналов: | CJ22: 8
G24: =ROUNDUP(H38/H26,0) -> 1 | M24: =ROUNDUP(N38/N26,0) -> 3 | U24: =ROUNDUP(V38/V26,0) -> 5 | X24: =ROUNDUP(Y38/Y26,0) -> 6 | AD24: =ROUNDUP(AE38/AE26,0) -> 8 | AJ24: =ROUNDUP(AK38/AK26,0) -> 10 | AU24: =ROUNDUP(AV38/AV26,0) -> 12 | BA24: =ROUNDUP(BB38/BB26,0) -> 14 | BI24: =ROUNDUP(BJ38/BJ26,0) -> 16 | BO24: =ROUNDUP(BP38/BP26,0) -> 18 | BR24: =ROUNDUP(BS38/BS26,0) -> 23 | CE24: =ROUNDUP(CF38/CF26,0) -> 21
G25: ='1'!C49 -> ЛПА-350-110 | M25: ='1'!C50 -> БИ-004-Б | U25: ='1'!C51 -> ЛПА-151-111 | X25: ='1'!C52 -> ЛПА-310-100 | AD25: ='1'!C52 -> ЛПА-310-100 | AJ25: ='1'!C52 -> ЛПА-310-100 | AU25: ='1'!C52 -> ЛПА-310-100 | BA25: ='1'!C52 -> ЛПА-310-100 | BI25: ='1'!$C$53 -> ЛПА-340-100 | BO25: ='1'!$C$54 -> ЛПА-340-100 | BR25: ='1'!C55 -> ЛПА-142-101 | CE25: ='1'!$C$53 -> ЛПА-340-100
G26: Каналов: | H26: =VLOOKUP(G25,Service!$E$151:$F$162,2,0) -> 1 | M26: Каналов: | N26: =VLOOKUP(M25,Service!E163:F174,2,0) -> 1 | U26: Каналов: | V26: =VLOOKUP(U25,Service!E175:F186,2,0) -> 1 | X26: Каналов: | Y26: =VLOOKUP(X25,Service!$E$187:$F$198,2,0) -> 1 | AD26: Каналов: | AE26: =VLOOKUP(AD25,Service!$E$187:$F$198,2,0) -> 1 | AJ26: Каналов: | AK26: =VLOOKUP(AJ25,Service!$E$187:$F$198,2,0) -> 1 | AU26: Каналов: | AV26: =VLOOKUP(AU25,Service!$E$187:$F$198,2,0) -> 1 | BA26: Каналов: | BB26: =VLOOKUP(BA25,Service!$E$187:$F$198,2,0) -> 1 | BI26: Каналов: | BJ26: =VLOOKUP(BI25,Service!$E$199:$F$209,2,0) -> 1 | BO26: Каналов: | BP26: =VLOOKUP(BO25,Service!$E$210:$F$220,2,0) -> 1 | BR26: Каналов: | BS26: =VLOOKUP(BR25,Service!E221:F227,2,0) -> 1 | CE26: Каналов: | CF26: =VLOOKUP(CE25,Service!$E$199:$F$209,2,0) -> 1
G28: Провод | J28: Провод | M28: Провод | P28: Провод | U28: Провод | X28: Провод | AA28: Провод | AD28: Провод | AG28: Провод | AJ28: Провод | AM28: Провод | AU28: Провод | AX28: Провод | BA28: Провод | BD28: Провод | BI28: Провод | BL28: Провод | BO28: Провод | BR28: Провод | BU28: Провод | BY28: Провод | CB28: Провод | CE28: Провод | CH28: Провод
G29: 2 метра | J29: 2 метра | M29: 2 метра | P29: 2 метра | U29: 2 метра | X29: 2 метра | AA29: 2 метра | AD29: 2 метра | AG29: 2 метра | AJ29: 2 метра | AM29: 2 метра | AU29: 2 метра | AX29: 2 метра | BA29: 2 метра | BD29: 2 метра | BI29: 2 метра | BL29: 2 метра | BO29: 2 метра | BR29: 2 метра | BU29: 2 метра | BY29: 2 метра | CB29: 2 метра | CE29: 2 метра | CH29: 2 метра
G30: =G34 -> 2 | J30: =J34 -> 4 | M30: =M34 -> 12 | P30: =P34 -> 16 | U30: =U34 -> 20 | X30: =X34 -> 12 | AA30: =AA34 -> 14 | AD30: =AD34 -> 16 | AG30: =AG34 -> 18 | AJ30: =AJ34 -> 20 | AM30: =AM34 -> 22 | AU30: =AU34 -> 24 | AX30: =AX34 -> 26 | BA30: =BA34 -> 28 | BD30: =BD34 -> 30 | BI30: =BI34 -> 32 | BL30: =BL34 -> 34 | BO30: =BO34 -> 36 | BR30: =BR34 -> 46 | BU30: =BU34 -> 48 | BY30: =BY34 -> 38 | CB30: =CB34 -> 40 | CE30: =CE34 -> 42 | CH30: =CH34 -> 44
G32: клемма | J32: клемма | M32: клемма | P32: клемма | U32: клемма | X32: клемма | AA32: клемма | AD32: клемма | AG32: клемма | AJ32: клемма | AM32: клемма | AU32: клемма | AX32: клемма | BA32: клемма | BD32: клемма | BI32: клемма | BL32: клемма | BO32: клемма | BR32: клемма | BU32: клемма | BY32: клемма | CB32: клемма | CE32: клемма | CH32: клемма
G33: DC4 | J33: DC4 | M33: DC4 | P33: DC4 | U33: DC4 | X33: DC4 | AA33: DC4 | AD33: DC4-HE | AG33: DC4-HE | AJ33: DC4-HE | AM33: DC4-HE | AU33: DC4-HE | AX33: DC4-HE | BA33: DC4-HE | BD33: DC4-HE | BI33: DC4 | BL33: DC4 | BO33: DC4 | BR33: DC4 | BU33: DC4 | BY33: DC4 | CB33: DC4 | CE33: DC4 | CH33: DC4 | DC33: клем+пред | DD33: клем для стабил. | DE33: стабил. | DF33: Клемма
G34: =H38*H37 -> 2 | J34: =K38*K37 -> 4 | M34: =N38*N37 -> 12 | P34: =Q38*Q37 -> 16 | U34: =V38*V37 -> 20 | X34: =Y38*Y37 -> 12 | AA34: =AB38*AB37 -> 14 | AD34: =AE38*AE37 -> 16 | AG34: =AH38*AH37 -> 18 | AJ34: =AK38*AK37 -> 20 | AM34: =AN38*AN37 -> 22 | AU34: =AV38*AV37 -> 24 | AX34: =AY38*AY37 -> 26 | BA34: =BB38*BB37 -> 28 | BD34: =BE38*BE37 -> 30 | BI34: =BJ38*BJ37 -> 32 | BL34: =BM38*BM37 -> 34 | BO34: =BP38*BP37 -> 36 | BR34: =BS38*BS37 -> 46 | BU34: =BV38*BV37 -> 48 | BY34: =BZ38*BZ37 -> 38 | CB34: =CC38*CC37 -> 40 | CE34: =CF38*CF37 -> 42 | CH34: =CI38*CI37 -> 44 | CM34: =CN38 -> 0 | CN34: =CN38 -> 0 | CP34: =CQ38 -> 0 | CQ34: =CQ38 -> 0 | CV34: =CW38 -> 0 | CW34: =CW38 -> 0 | CY34: =CZ38 -> 0 | CZ34: =CZ38 -> 0 | DC34: DC4-HE-01P-13-00Z(H) | DD34: DS2.5-QU-01P-11-00Z(H) | DE34: BZX55C4V7 | DF34: DC2.5-01P-11-00Z(H)
DC35: =SUM(AD34:BE34)/2 -> 92 | DD35: =DC35*3 -> 276 | DE35: =DC35*2 -> 184 | DF35: =SUM(G34:DA34)-DC35 -> 532
G36: AI TC Exi | J36: AI TC | M36: AI RTD Exi | P36: AI RTD | U36: ='1'!K5 -> RTD > 4-20 мА | X36: AI Exi 0-10 В | AA36: AI 0-10 В | AD36: AI Exi 4-20 мА | AG36: AI 4-20 мА | AJ36: AI Exi 4-20 мА HART | AM36: AI 4-20 мА HART | AU36: AO Exi 4-20 мА HART | AX36: AO 4-20 мА HART | BA36: AO Exi 4-20 мА | BD36: AO 4-20 мА | BI36: DI Exi 24 В | BL36: DI 24 В | BO36: DI NAMUR 24 В | BR36: FI Exi | BU36: Fi | BY36: DI 220 В | CB36: DO 220 В реле | CE36: DO Exi 24 В | CH36: DO 24 В | CM36: ='1'!AF4 -> Ethernet | CP36: ='1'!AG4 -> Profibus DP | CS36: ='1'!AH4 -> Foundation Fieldbus | CV36: Modbus RS-232 | CY36: Modbus RS-485
G37: Провода: | H37: 2 | J37: Провода: | K37: 2 | M37: Провода: | N37: 4 | P37: Провода: | Q37: 4 | U37: Провода: | V37: 4 | X37: Провода: | Y37: 2 | AA37: Провода: | AB37: 2 | AD37: Провода: | AE37: 2 | AG37: Провода: | AH37: 2 | AJ37: Провода: | AK37: 2 | AM37: Провода: | AN37: 2 | AU37: Провода: | AV37: 2 | AX37: Провода: | AY37: 2 | BA37: Провода: | BB37: 2 | BD37: Провода: | BE37: 2 | BI37: Провода: | BJ37: 2 | BL37: Провода: | BM37: 2 | BO37: Провода: | BP37: 2 | BR37: Провода: | BS37: 2 | BU37: Провода: | BV37: 2 | BY37: Провода: | BZ37: 2 | CB37: Провода: | CC37: 2 | CE37: Провода: | CF37: 2 | CH37: Провода: | CI37: 2 | CM37: Провода: | CN37: 1 | CP37: Провода: | CQ37: 1 | CS37: Провода: | CT37: 1 | CV37: Провода: | CW37: 2 | CY37: Провода: | CZ37: 2
G38: Сигналов: | H38: ='1'!$G$10 -> 1 | J38: Сигналов: | K38: ='1'!$H$10 -> 2 | M38: Сигналов: | N38: ='1'!$I$10 -> 3 | P38: Сигналов: | Q38: ='1'!$J$10 -> 4 | U38: Сигналов: | V38: ='1'!K10 -> 5 | X38: Сигналов: | Y38: ='1'!$L$10 -> 6 | AA38: Сигналов: | AB38: ='1'!$M$10 -> 7 | AD38: Сигналов: | AE38: ='1'!$N$10 -> 8 | AG38: Сигналов: | AH38: ='1'!$O$10 -> 9 | AJ38: Сигналов: | AK38: ='1'!$P$10 -> 10 | AM38: Сигналов: | AN38: ='1'!$Q$10 -> 11 | AU38: Сигналов: | AV38: ='1'!$R$10 -> 12 | AX38: Сигналов: | AY38: ='1'!$S$10 -> 13 | BA38: Сигналов: | BB38: ='1'!$T$10 -> 14 | BD38: Сигналов: | BE38: ='1'!$U$10 -> 15 | BI38: Сигналов: | BJ38: ='1'!$V$10 -> 16 | BL38: Сигналов: | BM38: ='1'!$W$10 -> 17 | BO38: Сигналов: | BP38: ='1'!$X$10 -> 18 | BR38: Сигналов: | BS38: ='1'!$AC$10 -> 23 | BU38: Сигналов: | BV38: ='1'!$AD$10 -> 24 | BY38: Сигналов: | BZ38: ='1'!$Y$10 -> 19 | CB38: Сигналов: | CC38: ='1'!$Z$10 -> 20 | CE38: Сигналов: | CF38: ='1'!$AA$10 -> 21 | CH38: Сигналов: | CI38: ='1'!$AB$10 -> 22 | CM38: Сигналов: | CN38: ='1'!AF10 -> 0 | CP38: Сигналов: | CQ38: ='1'!AG10 -> 0 | CS38: Сигналов: | CT38: ='1'!AH10 -> 0 | CV38: Сигналов: | CW38: ='1'!AI10 -> 0 | CY38: Сигналов: | CZ38: ='1'!AJ10 -> 0

Sheet 1 расположение
